<?xml version="1.0"?>

<robot xmlns:sensor="http://playerstage.sourceforge.net/gazebo/xmlschema/#sensor"
       xmlns:controller="http://playerstage.sourceforge.net/gazebo/xmlschema/#controller"
       xmlns:interface="http://playerstage.sourceforge.net/gazebo/xmlschema/#interface"
       xmlns:xacro="http://ros.org/wiki/xacro"
>

<!-- Chassis -->
	<link name="base_link">
		<inertial>
			<mass value="10.0"/>
			<origin xyz="0 0 0.177"/>
			<inertia ixx="0.3338" ixy="0.0" ixz="0.0"
				 iyy="90.9783" iyz="0.0"
				 izz="0.3338"/>


		</inertial>
		<visual name="base_visual">
			<origin xyz="0 0 0.177" rpy="0 0 0"/>
			<geometry name="pioneer_geom">
				<mesh filename="package://setup/models/p3at/meshes/chassis.stl"/>
			</geometry>
			<material name="ChassisRed">
				<color rgba="0.851 0.0 0.0 1.0"/>
			</material>
		</visual>
		<collision>
			<origin xyz="0 0 0.177" rpy="0 0 0"/>
				<geometry>
					<mesh filename="package://setup/models/p3at/meshes/chassis.stl"/>
				</geometry>
		</collision>
	</link>
	<gazebo reference="base_link">
		<material value="Gazebo/Red"/>
	</gazebo>

<!-- Top -->
	<link name="top_plate">
		<inertial>
			<mass value="0.1"/>
			<origin xyz="-0.025 0 -0.223"/>
			<inertia ixx="1.0" ixy="0.0" ixz="0.0"
				 iyy="1.0" iyz="0.0"
 				izz="1.0"/>
		</inertial>
		<visual name="base_visual">
			<origin xyz="0 0 0" rpy="0 0 0"/>
			<geometry name="pioneer_geom">
				<mesh filename="package://setup/models/p3at/meshes/top.stl"/>
			</geometry>
			<material name="TopBlack">
					<color rgba="0.038 0.038 0.038 1.0"/>
			</material>
		</visual>
		<collision>
			<origin xyz="0 0 0" rpy="0 0 0"/>
			<geometry>
				<box size="0 0 0"/>
			</geometry>
		</collision>
	</link>
	<gazebo reference="top_plate">
		<material value="Gazebo/Black"/>
	</gazebo>

	<joint name="base_top_joint" type="fixed">
		<origin xyz="0.003 0 0.274" rpy="0 0 0"/>
		<parent link="base_link"/>
		<child link="top_plate"/>
	</joint>
<!-- Front + Back Sonar -->
	<link name="front_sonar">
		<inertial>
			<mass value="0.1"/>
			<origin xyz="0 0 0"/>
			<inertia ixx="1.0" ixy="0.0" ixz="0.0"
				 iyy="1.0" iyz="0.0" izz="1.0"/>
		</inertial>
		<visual name="base_visual">
			<origin xyz="0 0 0" rpy="0 0 0"/>
			<geometry name="pioneer_geom">
				<mesh filename="package://setup/models/p3at/meshes/front_sonar.stl"/>
			</geometry>
			<material name="SonarYellow">
				<color rgba="0.715 0.583 0.210 1.0"/>
			</material>
		</visual>
		<collision>
			<origin xyz="0 0 0" rpy="0 0 0"/>
			<geometry>
				<box size="0 0 0"/>
			</geometry>
		</collision>
	</link>
	<gazebo reference="front_sonar">
		<material value="Gazebo/Yellow"/>
	</gazebo>

	<joint name="base_front_joint" type="fixed">
		<origin xyz="0.193 0 0.25" rpy="0 0 0"/>
		<parent link="base_link"/>
		<child link="front_sonar"/>
	</joint>

	<link name="back_sonar">
		<inertial>
			<mass value="0.1"/>
			<origin xyz="0 0 0"/>
			<inertia ixx="1.0" ixy="0.0" ixz="0.0"
				 iyy="1.0" iyz="0.0" izz="1.0"/>
		</inertial>
		<visual name="base_visual">
			<origin xyz="0 0 0" rpy="0 0 0"/>
			<geometry name="pioneer_geom">
				<mesh filename="package://setup/models/p3at/meshes/back_sonar.stl"/>
			</geometry>
			<material name="SonarYellow">
				<color rgba="0.715 0.583 0.210 1.0"/>
			</material>
		</visual>
		<collision>
			<origin xyz="0 0 0" rpy="0 0 0"/>
			<geometry>
				<box size="0 0 0"/>
			</geometry>
		</collision>
	</link>
	<gazebo reference="back_sonar">
		<material value="Gazebo/Yellow"/>
	</gazebo>

	<joint name="base_back_joint" type="fixed">
		<origin xyz="-0.187 0 0.247" rpy="0 0 0"/>
		<parent link="base_link"/>
		<child link="back_sonar"/>
	</joint>

<!-- Front Axles + Wheels + Hubcaps -->
<xacro:macro name="p3at_front" params="suffix reflect">
	<link name="p3at_front_${suffix}_axle">
		<inertial>
			<mass value="0.1"/>
			<origin xyz="0 0 0"/>
			<inertia ixx="1.0" ixy="0.0" ixz="0.0"
				 iyy="1.0" iyz="0.0" izz="1.0"/>
  	 	</inertial>
	<visual name="base_visual">
		<origin xyz="0 0 0" rpy="0 0 0"/>
		<geometry name="pioneer_geom">
			<mesh filename="package://setup/models/p3at/meshes/axle.stl"/>
		</geometry>
		<material name="AxleGrey">
			<color rgba="0.5 0.5 0.5 1"/>
		</material>
	</visual>
	<collision>
		<origin xyz="0 0 0" rpy="0 0 0"/>
		<geometry>
			<box size="0 0 0"/>
		</geometry>
	</collision>
	</link>
	<gazebo reference="p3at_front_${suffix}_axle">
		<material value="Gazebo/Grey"/>
	</gazebo>

	<joint name="base_front_${suffix}_axle_joint" type="fixed">
		<origin xyz="0.135 ${reflect*0.156} 0.111" rpy="0 0 0"/>
		<parent link="base_link"/>
		<child link="p3at_front_${suffix}_axle"/>
	</joint>

	<link name="p3at_front_${suffix}_hub">
		<inertial>
			<mass value="0.1"/>
			<origin xyz="0 0 0"/>
			<inertia ixx="1.0" ixy="0.0" ixz="0.0"
				 iyy="1.0" iyz="0.0" izz="1.0"/>
  	 	</inertial>
	<visual name="base_visual">
		<origin xyz="0 0 0" rpy="0 0 0"/>
		<geometry name="pioneer_geom">
			<mesh filename="package://setup/models/p3at/meshes/${suffix}_hubcap.stl"/>
		</geometry>
		<material name="HubcapYellow">
			<color rgba="1.0 0.811 0.151 1.0"/>
		</material>
	</visual>
	<collision>
		<origin xyz="0 0 0" rpy="0 0 0"/>
		<geometry>
			<box size="0 0 0"/>
		</geometry>
	</collision>
	</link>
	<gazebo reference="p3at_front_${suffix}_hub">
		<material value="Gazebo/Yellow"/>
	</gazebo>

	<joint name="base_front_${suffix}_hub_joint" type="fixed">
		<origin xyz="0 ${reflect*0.041} 0" rpy="0 0 0"/>
		<parent link="p3at_front_${suffix}_axle"/>
		<child link="p3at_front_${suffix}_hub"/>
	</joint>

	<link name="p3at_front_${suffix}_wheel">
		<inertial>
			<mass value="2.5"/>
			<origin xyz="0 0 0"/>
			<inertia ixx="0.012411765597" ixy="0" ixz="0"
         iyy="0.015218160428" iyz="0" izz="0.011763977943"/>
      </inertial>
	<visual name="base_visual">
		<origin xyz="0 0 0" rpy="0 0 0"/>
		<geometry name="pioneer_geom">
			<mesh filename="package://setup/models/p3at/meshes/wheel.stl"/>
		</geometry>
		<material name="WheelBlack">
			<color rgba="0.117 0.117 0.117 1"/>
		</material>
	</visual>
	<collision>
		<origin xyz="0 0 0" rpy="${-3.1415927/2} 0 0"/>
		<geometry>
	    <!--mesh filename="package://setup/meshes/wheel.stl"/-->
	    <cylinder radius="0.111" length="0.075"/>
		</geometry>
	</collision>
	</link>
	<gazebo reference="p3at_front_${suffix}_wheel">
		<material value="Gazebo/Black"/>
	</gazebo>

	<joint name="p3at_front_${suffix}_wheel_joint" type="continuous">
  	<axis xyz="0 1 0"/>
    <anchor xyz="0 0 0"/>
    <limit effort="100" velocity="100" />
    <joint_properties damping="0.7"/>
		<origin xyz="0 0 0" rpy="0 0 0"/>
		<parent link="p3at_front_${suffix}_hub"/>
		<child link="p3at_front_${suffix}_wheel"/>
	</joint>
</xacro:macro>
<!-- Back Axles + Wheels + Hubcaps -->
<xacro:macro name="p3at_back" params="suffix reflect">
	<link name="p3at_back_${suffix}_axle">
		<inertial>
			<mass value="0.1"/>
			<origin xyz="0 0 0"/>
			<inertia ixx="1.0" ixy="0.0" ixz="0.0"
				 iyy="1.0" iyz="0.0" izz="1.0"/>
  	 	</inertial>
	<visual name="base_visual">
		<origin xyz="0 0 0" rpy="0 0 0"/>
		<geometry name="pioneer_geom">
			<mesh filename="package://setup/models/p3at/meshes/axle.stl"/>
		</geometry>
		<material name="AxleGrey">
			<color rgba="0.5 0.5 0.5 1"/>
		</material>
	</visual>
	<collision>
		<origin xyz="0 0 0" rpy="0 0 0"/>
		<geometry>
			<mesh filename="package://setup/models/p3at/meshes/axle.stl"/>
		</geometry>
	</collision>
	</link>
	<gazebo reference="p3at_back_${suffix}_axle">
		<material value="Gazebo/Grey"/>
	</gazebo>

	<joint name="bp3at_back_${suffix}_axle_joint" type="fixed">
		<origin xyz="-0.134 ${reflect*0.156} 0.111" rpy="0 0 0"/>
		<parent link="base_link"/>
		<child link="p3at_back_${suffix}_axle"/>
	</joint>


	<link name="p3at_back_${suffix}_hub">
		<inertial>
			<mass value="0.1"/>
			<origin xyz="0 0 0"/>
			<inertia ixx="1.0" ixy="0.0" ixz="0.0"
				 iyy="1.0" iyz="0.0" izz="1.0"/>
  	 	</inertial>
	<visual name="base_visual">
		<origin xyz="0 0 0" rpy="0 0 0"/>
		<geometry name="pioneer_geom">
			<mesh filename="package://setup/models/p3at/meshes/${suffix}_hubcap.stl"/>
		</geometry>
		<material name="HubcapYellow"/>
	</visual>
	<collision>
		<origin xyz="0 0 0" rpy="0 0 0"/>
		<geometry>
			<mesh filename="package://setup/models/p3at/meshes/${suffix}_hubcap.stl"/>
		</geometry>
	</collision>
	</link>
	<gazebo reference="p3at_back_${suffix}_hub">
		<material value="Gazebo/Yellow"/>
	</gazebo>

	<joint name="p3at_back_${suffix}_hub_joint" type="fixed">
		<origin xyz="-0 ${reflect*0.041} 0" rpy="0 0 0"/>
		<parent link="p3at_back_${suffix}_axle"/>
		<child link="p3at_back_${suffix}_hub"/>
	</joint>

	<link name="p3at_back_${suffix}_wheel">
		<inertial>
			<mass value="2.5"/>
			<origin xyz="0 0 0"/>
			<inertia ixx="0.012411765597" ixy="0" ixz="0"
         iyy="0.015218160428" iyz="0" izz="0.011763977943"/>
      </inertial>
	<visual name="base_visual">
		<origin xyz="0 0 0" rpy="0 0 0"/>
		<geometry name="pioneer_geom">
			<mesh filename="package://setup/models/p3at/meshes/wheel.stl"/>
		</geometry>
		<material name="WheelBlack"/>
	</visual>
	<collision>
		<origin xyz="0 0 0" rpy="${-3.1415927/2} 0 0"/>
		<geometry>
	    <!--mesh filename="package://setup/meshes/wheel.stl"/-->
	    <cylinder radius="0.111" length="0.075"/>
		</geometry>
	</collision>
	</link>
	<gazebo reference="p3at_back_${suffix}_wheel">
		<material value="Gazebo/Black"/>
	</gazebo>

	<joint name="p3at_back_${suffix}_wheel_joint" type="continuous">
	  <axis xyz="0 1 0"/>
    <anchor xyz="0 0 0"/>
    <limit effort="100" velocity="100" />
    <joint_properties damping="0.7"/>
		<origin xyz="0 0 0" rpy="0 0 0"/>
		<parent link="p3at_back_${suffix}_hub"/>
		<child link="p3at_back_${suffix}_wheel"/>
	</joint>

  <gazebo reference="p3at_back_${suffix}_wheel">
    <kp>1000000.0</kp> <!-- kp and kd for rubber -->
    <kd>100.0</kd>
    <mu1>10.0</mu1>
    <mu2>1.0</mu2>
    <fdir1>0 1 0</fdir1> <!-- is this correct? -->
    <maxVel>1.0</maxVel>
    <minDepth>0.00</minDepth>
  </gazebo>

  <gazebo reference="p3at_front_${suffix}_wheel">
    <kp>1000000.0</kp> <!-- kp and kd for rubber -->
    <kd>100.0</kd>
    <mu1>10.0</mu1>
    <mu2>1.0</mu2>
    <fdir1>0 1 0</fdir1> <!-- is this correct? -->
    <maxVel>1.0</maxVel>
    <minDepth>0.00</minDepth>
  </gazebo>

</xacro:macro>

<xacro:macro name="hokuyo_ust20lx" params="laser_prefix parent *origin">
    <joint name="${laser_prefix}_laser_joint" type="fixed">
        <xacro:insert_block name="origin" />
        <parent link="${parent}" />
        <child link="${laser_prefix}_laser_link" />
    </joint>

    <link name="${laser_prefix}_laser_link">
        <visual>
        <geometry>
            <box size="0.05 0.05 0.05"/>
        </geometry>
        </visual>
        <collision>
            <geometry>
                <box size="0.05 0.05 0.05"/>
            </geometry>
        </collision>
    </link>

    <gazebo reference="${laser_prefix}_laser_link">
        <sensor type="ray" name="${laser_prefix}_hokuyo_laser">
            <pose>0 0 0 0 0 0</pose>
            <visualize>false</visualize>
            <update_rate>25</update_rate>
            <ray>
                <scan>
                    <horizontal>
                    <samples>540</samples>
                    <resolution>1</resolution>
                    <min_angle>-1.2</min_angle>
                    <max_angle>1.2</max_angle>
                    </horizontal>
                </scan>
                <range>
                    <min>0.05</min>
                    <max>25.0</max>
                    <resolution>0.05</resolution>
                </range>
                <!--noise>
                    <type>gaussian</type>
                    <mean>0.0</mean>
                    <stddev>0.01</stddev>
                </noise-->
            </ray>
            <plugin name="hokuyo_node" filename="libgazebo_ros_laser.so">
                <topicName>${laser_prefix}_scan</topicName>
                <frameName>${laser_prefix}_laser_link</frameName>
            </plugin>
        </sensor>
    </gazebo>

</xacro:macro>






<xacro:macro name="pgr_flea3" params="camera_prefix parent *origin">
    <joint name="${camera_prefix}_camera_joint" type="fixed">
        <xacro:insert_block name="origin" />
        <parent link="${parent}" />
        <child link="${camera_prefix}_camera_link" />
    </joint>

    <link name="${camera_prefix}_camera_link">
    <visual>
    <geometry>
        <box size="0.05 0.05 0.05"/>
    </geometry>
    </visual>
    <collision>
        <geometry>
            <box size="0.05 0.05 0.05"/>
        </geometry>
    </collision>
    </link>

    <gazebo reference="${camera_prefix}_camera_link">
        <sensor type="camera" name="${camera_prefix}_camera_sensor">
            <always_on>true</always_on>
            <visualize>false</visualize>
            <update_rate>25.0</update_rate>
            <camera>
                <horizontal_fov>1.3962634</horizontal_fov>
                <image>
                    <format>R8G8B8</format>
                    <width>250</width>
                    <height>250</height>
                </image>
                <clip>
                    <near>0.5</near>
                    <far>50</far>
                </clip>
            </camera>
            <plugin name="${camera_prefix}_camera_controller" filename="libgazebo_ros_camera.so">
                <alwaysOn>true</alwaysOn>
                <updateRate>25.0</updateRate>
                <cameraName>${camera_prefix}_camera</cameraName>
                <imageTopicName>${camera_prefix}_camera_image</imageTopicName>
                <cameraInfoTopicName>${camera_prefix}_camera_info</cameraInfoTopicName>
                <frameName>${camera_prefix}_camera_link</frameName>
                <hackBaseline>0</hackBaseline>
                <CxPrime>125.5</CxPrime>
                <Cx>125.5</Cx>
                <Cy>125.5</Cy>
                <focalLength>317.772992</focalLength>
                <distortionK1>0.0</distortionK1>
                <distortionK2>0.0</distortionK2>
                <distortionK3>0.0</distortionK3>
                <distortionT1>0.0</distortionT1>
                <distortionT2>0.0</distortionT2>
            </plugin>
        </sensor>
    </gazebo>

</xacro:macro>




<xacro:macro name="p3at_gazebo_ext">

<gazebo>
  <plugin name="skid_steer_drive_controller" filename="libgazebo_ros_skid_steer_drive.so">
    <updateRate>100.0</updateRate>
    <leftFrontJoint>p3at_front_left_wheel_joint</leftFrontJoint>
    <rightFrontJoint>p3at_front_right_wheel_joint</rightFrontJoint>
    <leftRearJoint>p3at_back_left_wheel_joint</leftRearJoint>
    <rightRearJoint>p3at_back_right_wheel_joint</rightRearJoint>
    <wheelSeparation>0.4</wheelSeparation>
    <wheelDiameter>0.215</wheelDiameter>
    <robotBaseFrame>base_link</robotBaseFrame>
    <torque>200</torque>
    <topicName>cmd_vel</topicName>
    <odometryTopic>odom</odometryTopic>
    <broadcastTF>1</broadcastTF>
    <odometryFrame>odom</odometryFrame>

  </plugin>
</gazebo>

</xacro:macro>

</robot>
